2024-02-27 15:34:11,495 - LogController.py[line:87] - ERROR: Traceback (most recent call last):
  File "C:\Users\YGS_Tu\Desktop\code\python\qt0223\controller\PicController.py", line 55, in run
    Main = img_main()
TypeError: 'module' object is not callable

2024-02-27 15:34:11,498 - LogController.py[line:87] - ERROR: Traceback (most recent call last):
  File "C:\Users\YGS_Tu\Desktop\code\python\qt0223\controller\PicController.py", line 55, in run
    Main = img_main()
TypeError: 'module' object is not callable

2024-02-27 15:59:15,173 - LogController.py[line:87] - ERROR: Traceback (most recent call last):
  File "C:\Users\YGS_Tu\Desktop\code\python\qt0223\..\qt0223\view\LoadPage.py", line 252, in changePage
    self.cur_page = globals()[msg]()
  File "C:\Users\YGS_Tu\Desktop\code\python\qt0223\..\qt0223\view\HistoryPage.py", line 50, in __init__
    self.InitUI()
  File "C:\Users\YGS_Tu\Desktop\code\python\qt0223\..\qt0223\view\HistoryPage.py", line 74, in InitUI
    self.setTableWidget()
  File "C:\Users\YGS_Tu\Desktop\code\python\qt0223\..\qt0223\view\HistoryPage.py", line 495, in setTableWidget
    text = MyReport().gethtml()
TypeError: gethtml() missing 3 required positional arguments: 'item_type', 'reagent_info', and 'nature_aver_str'

2024-02-27 16:55:32,173 - LogController.py[line:87] - ERROR: Traceback (most recent call last):
  File "C:\Users\YGS_Tu\Desktop\code\python\qt0223\view\LoadPage.py", line 252, in changePage
    self.cur_page = globals()[msg]()
  File "C:\Users\YGS_Tu\Desktop\code\python\qt0223\view\HistoryPage.py", line 50, in __init__
    self.InitUI()
  File "C:\Users\YGS_Tu\Desktop\code\python\qt0223\view\HistoryPage.py", line 74, in InitUI
    self.setTableWidget()
  File "C:\Users\YGS_Tu\Desktop\code\python\qt0223\view\HistoryPage.py", line 495, in setTableWidget
    text = MyReport().gethtml()
TypeError: gethtml() missing 3 required positional arguments: 'item_type', 'reagent_info', and 'nature_aver_str'

2024-02-27 17:15:32,559 - LogController.py[line:87] - ERROR: Traceback (most recent call last):
  File "C:\Users\YGS_Tu\Desktop\code\python\qt0223\..\qt0223\view\LoadPage.py", line 252, in changePage
    self.cur_page = globals()[msg]()
KeyError: 'dataPage'

2024-02-27 17:28:31,726 - LogController.py[line:87] - ERROR: Traceback (most recent call last):
  File "C:\Users\YGS_Tu\Desktop\code\python\qt0223\..\qt0223\view\DataPage.py", line 206, in getData
    self.setTableWidget(self.data['item_type'], self.allergy_info, self.data['nature_aver_str'])
  File "C:\Users\YGS_Tu\Desktop\code\python\qt0223\..\qt0223\view\DataPage.py", line 293, in setTableWidget
    text = MyReport().gethtml(item_type, reagent_info, nature_aver_str)
  File "C:\Users\YGS_Tu\Desktop\code\python\qt0223\..\qt0223\util\report.py", line 118, in gethtml
    temp_str = temp_str + str_temp % (str(j + 1) + reagent_info_list_3[j], result_list_3[j], result_list_4[j])
IndexError: list index out of range

2024-02-27 17:28:31,729 - LogController.py[line:87] - ERROR: Traceback (most recent call last):
  File "C:\Users\YGS_Tu\Desktop\code\python\qt0223\..\qt0223\view\DataPage.py", line 206, in getData
    self.setTableWidget(self.data['item_type'], self.allergy_info, self.data['nature_aver_str'])
  File "C:\Users\YGS_Tu\Desktop\code\python\qt0223\..\qt0223\view\DataPage.py", line 293, in setTableWidget
    text = MyReport().gethtml(item_type, reagent_info, nature_aver_str)
  File "C:\Users\YGS_Tu\Desktop\code\python\qt0223\..\qt0223\util\report.py", line 118, in gethtml
    temp_str = temp_str + str_temp % (str(j + 1) + reagent_info_list_3[j], result_list_3[j], result_list_4[j])
IndexError: list index out of range

2024-02-27 17:29:02,914 - LogController.py[line:87] - ERROR: Traceback (most recent call last):
  File "C:\Users\YGS_Tu\Desktop\code\python\qt0223\..\qt0223\view\DataPage.py", line 206, in getData
    self.setTableWidget(self.data['item_type'], self.allergy_info, self.data['nature_aver_str'])
  File "C:\Users\YGS_Tu\Desktop\code\python\qt0223\..\qt0223\view\DataPage.py", line 293, in setTableWidget
    text = MyReport().gethtml(item_type, reagent_info, nature_aver_str)
  File "C:\Users\YGS_Tu\Desktop\code\python\qt0223\..\qt0223\util\report.py", line 118, in gethtml
    temp_str = temp_str + str_temp % (str(j + 1) + reagent_info_list_3[j], result_list_3[j], result_list_4[j])
IndexError: list index out of range

2024-02-27 17:29:02,917 - LogController.py[line:87] - ERROR: Traceback (most recent call last):
  File "C:\Users\YGS_Tu\Desktop\code\python\qt0223\..\qt0223\view\DataPage.py", line 206, in getData
    self.setTableWidget(self.data['item_type'], self.allergy_info, self.data['nature_aver_str'])
  File "C:\Users\YGS_Tu\Desktop\code\python\qt0223\..\qt0223\view\DataPage.py", line 293, in setTableWidget
    text = MyReport().gethtml(item_type, reagent_info, nature_aver_str)
  File "C:\Users\YGS_Tu\Desktop\code\python\qt0223\..\qt0223\util\report.py", line 118, in gethtml
    temp_str = temp_str + str_temp % (str(j + 1) + reagent_info_list_3[j], result_list_3[j], result_list_4[j])
IndexError: list index out of range

2024-02-27 17:33:08,280 - LogController.py[line:87] - ERROR: Traceback (most recent call last):
  File "C:\Users\YGS_Tu\Desktop\code\python\qt0223\..\qt0223\view\DataPage.py", line 206, in getData
    self.setTableWidget(self.data['item_type'], self.allergy_info, self.data['nature_aver_str'])
  File "C:\Users\YGS_Tu\Desktop\code\python\qt0223\..\qt0223\view\DataPage.py", line 293, in setTableWidget
    text = MyReport().gethtml(item_type, reagent_info, nature_aver_str)
  File "C:\Users\YGS_Tu\Desktop\code\python\qt0223\..\qt0223\util\report.py", line 118, in gethtml
    temp_str = temp_str + str_temp % (str(j + 1) + reagent_info_list_3[j], result_list_3[j], result_list_4[j])
IndexError: list index out of range

2024-02-27 17:33:08,283 - LogController.py[line:87] - ERROR: Traceback (most recent call last):
  File "C:\Users\YGS_Tu\Desktop\code\python\qt0223\..\qt0223\view\DataPage.py", line 206, in getData
    self.setTableWidget(self.data['item_type'], self.allergy_info, self.data['nature_aver_str'])
  File "C:\Users\YGS_Tu\Desktop\code\python\qt0223\..\qt0223\view\DataPage.py", line 293, in setTableWidget
    text = MyReport().gethtml(item_type, reagent_info, nature_aver_str)
  File "C:\Users\YGS_Tu\Desktop\code\python\qt0223\..\qt0223\util\report.py", line 118, in gethtml
    temp_str = temp_str + str_temp % (str(j + 1) + reagent_info_list_3[j], result_list_3[j], result_list_4[j])
IndexError: list index out of range

2024-02-27 17:33:55,020 - LogController.py[line:87] - ERROR: Traceback (most recent call last):
  File "C:\Users\YGS_Tu\Desktop\code\python\qt0223\..\qt0223\view\DataPage.py", line 206, in getData
    self.setTableWidget(self.data['item_type'], self.allergy_info, self.data['nature_aver_str'])
  File "C:\Users\YGS_Tu\Desktop\code\python\qt0223\..\qt0223\view\DataPage.py", line 293, in setTableWidget
    text = MyReport().gethtml(item_type, reagent_info, nature_aver_str)
  File "C:\Users\YGS_Tu\Desktop\code\python\qt0223\..\qt0223\util\report.py", line 118, in gethtml
    temp_str = temp_str + str_temp % (str(j + 1) + reagent_info_list_3[j], result_list_3[j], result_list_4[j])
IndexError: list index out of range

2024-02-27 17:33:55,024 - LogController.py[line:87] - ERROR: Traceback (most recent call last):
  File "C:\Users\YGS_Tu\Desktop\code\python\qt0223\..\qt0223\view\DataPage.py", line 206, in getData
    self.setTableWidget(self.data['item_type'], self.allergy_info, self.data['nature_aver_str'])
  File "C:\Users\YGS_Tu\Desktop\code\python\qt0223\..\qt0223\view\DataPage.py", line 293, in setTableWidget
    text = MyReport().gethtml(item_type, reagent_info, nature_aver_str)
  File "C:\Users\YGS_Tu\Desktop\code\python\qt0223\..\qt0223\util\report.py", line 118, in gethtml
    temp_str = temp_str + str_temp % (str(j + 1) + reagent_info_list_3[j], result_list_3[j], result_list_4[j])
IndexError: list index out of range

2024-02-28 10:49:38,520 - LogController.py[line:87] - ERROR: Traceback (most recent call last):
  File "C:\Users\YGS_Tu\Desktop\code\python\qt0223\view\LoadPage.py", line 303, in showCurrentTime
    def showCurrentTime(self) -> None:
KeyboardInterrupt

2024-02-28 10:49:38,520 - LogController.py[line:87] - ERROR: Traceback (most recent call last):
  File "C:\Users\YGS_Tu\Desktop\code\python\qt0223\view\LoadPage.py", line 303, in showCurrentTime
    def showCurrentTime(self) -> None:
KeyboardInterrupt

2024-02-28 11:09:32,264 - LogController.py[line:87] - ERROR: Traceback (most recent call last):
  File "C:\Users\YGS_Tu\Desktop\code\python\qt0223\..\qt0223\view\LoadPage.py", line 264, in changePage
    self.cur_page = globals()[msg]()
KeyError: 'PerPage'

2024-02-28 11:10:35,479 - LogController.py[line:87] - ERROR: Traceback (most recent call last):
  File "C:\Users\YGS_Tu\Desktop\code\python\qt0223\..\qt0223\view\LoadPage.py", line 264, in changePage
    self.cur_page = globals()[msg]()
KeyError: 'PerPage'

2024-02-28 11:10:52,094 - LogController.py[line:87] - ERROR: Traceback (most recent call last):
  File "C:\Users\YGS_Tu\Desktop\code\python\qt0223\..\qt0223\view\LoadPage.py", line 264, in changePage
    self.cur_page = globals()[msg]()
KeyError: 'PerPage'

2024-02-28 11:18:15,573 - LogController.py[line:87] - ERROR: Traceback (most recent call last):
  File "C:\Users\YGS_Tu\Desktop\code\python\qt0223\..\qt0223\view\LoadPage.py", line 264, in changePage
    self.cur_page = globals()[msg]()
  File "C:\Users\YGS_Tu\Desktop\code\python\qt0223\..\qt0223\view\SysPage.py", line 31, in __init__
    self.InitUI()
  File "C:\Users\YGS_Tu\Desktop\code\python\qt0223\..\qt0223\view\SysPage.py", line 40, in InitUI
    self.setBtnIcon()
  File "C:\Users\YGS_Tu\Desktop\code\python\qt0223\..\qt0223\view\SysPage.py", line 72, in setBtnIcon
    self.ui.per_icon_label.setPixmap(pixImg)
AttributeError: 'Ui_Form' object has no attribute 'per_icon_label'

2024-02-28 11:18:50,632 - LogController.py[line:87] - ERROR: Traceback (most recent call last):
  File "C:\Users\YGS_Tu\Desktop\code\python\qt0223\..\qt0223\view\LoadPage.py", line 264, in changePage
    self.cur_page = globals()[msg]()
  File "C:\Users\YGS_Tu\Desktop\code\python\qt0223\..\qt0223\view\SysPage.py", line 31, in __init__
    self.InitUI()
  File "C:\Users\YGS_Tu\Desktop\code\python\qt0223\..\qt0223\view\SysPage.py", line 40, in InitUI
    self.setBtnIcon()
  File "C:\Users\YGS_Tu\Desktop\code\python\qt0223\..\qt0223\view\SysPage.py", line 72, in setBtnIcon
    """
AttributeError: 'Ui_Form' object has no attribute 'per_icon_label'

2024-02-28 16:15:23,382 - LogController.py[line:87] - ERROR: Traceback (most recent call last):
  File "C:\Users\YGS_Tu\Desktop\code\python\qt0223\..\qt0223\controller\PicController.py", line 52, in run
    Camera_Init_flag = Main.imgAcquire(
  File "C:\Users\YGS_Tu\Desktop\code\python\qt0223\..\qt0223\pic_code\img_main.py", line 42, in imgAcquire
    flag = self.Acq.img_acquire_log(path_chache, path_save, name)
  File "C:\Users\YGS_Tu\Desktop\code\python\qt0223\..\qt0223\pic_code\Code\code_acquire\acqRun.py", line 25, in img_acquire_log
    img = Image.open(path_chache + "1.jpeg")
  File "C:\Program Files\Python39\lib\site-packages\PIL\Image.py", line 3236, in open
    fp = builtins.open(filename, "rb")
FileNotFoundError: [Errno 2] No such file or directory: 'C:\\Users\\YGS_Tu\\Desktop\\code\\python\\qt0223\\..\\qt0223/third_party/img/pic_cache/1.jpeg'

2024-02-28 16:15:23,382 - LogController.py[line:87] - ERROR: Traceback (most recent call last):
  File "C:\Users\YGS_Tu\Desktop\code\python\qt0223\..\qt0223\controller\PicController.py", line 52, in run
    Camera_Init_flag = Main.imgAcquire(
  File "C:\Users\YGS_Tu\Desktop\code\python\qt0223\..\qt0223\pic_code\img_main.py", line 42, in imgAcquire
    flag = self.Acq.img_acquire_log(path_chache, path_save, name)
  File "C:\Users\YGS_Tu\Desktop\code\python\qt0223\..\qt0223\pic_code\Code\code_acquire\acqRun.py", line 25, in img_acquire_log
    img = Image.open(path_chache + "1.jpeg")
  File "C:\Program Files\Python39\lib\site-packages\PIL\Image.py", line 3236, in open
    fp = builtins.open(filename, "rb")
FileNotFoundError: [Errno 2] No such file or directory: 'C:\\Users\\YGS_Tu\\Desktop\\code\\python\\qt0223\\..\\qt0223/third_party/img/pic_cache/1.jpeg'

2024-02-28 16:20:03,970 - LogController.py[line:87] - ERROR: Traceback (most recent call last):
  File "C:\Users\YGS_Tu\Desktop\code\python\qt0223\..\qt0223\controller\PicController.py", line 64, in run
    judge_flag, self.gray_aver, self.nature_aver = Main.imgProcess(
  File "C:\Users\YGS_Tu\Desktop\code\python\qt0223\..\qt0223\pic_code\img_main.py", line 27, in imgProcess
    flag, gray, nature = self.Pro.process_log(path_read=read, path_write=write, combina=combina, radius=radius)
  File "C:\Users\YGS_Tu\Desktop\code\python\qt0223\..\qt0223\pic_code\Code\code_process\imgRun.py", line 33, in process_log
    img = cv.cvtColor(cv.imread(path_read), cv.COLOR_RGB2GRAY)
cv2.error: OpenCV(4.7.0) D:\a\opencv-python\opencv-python\opencv\modules\imgproc\src\color.cpp:182: error: (-215:Assertion failed) !_src.empty() in function 'cv::cvtColor'


2024-02-28 16:20:03,970 - LogController.py[line:87] - ERROR: Traceback (most recent call last):
  File "C:\Users\YGS_Tu\Desktop\code\python\qt0223\..\qt0223\controller\PicController.py", line 64, in run
    judge_flag, self.gray_aver, self.nature_aver = Main.imgProcess(
  File "C:\Users\YGS_Tu\Desktop\code\python\qt0223\..\qt0223\pic_code\img_main.py", line 27, in imgProcess
    flag, gray, nature = self.Pro.process_log(path_read=read, path_write=write, combina=combina, radius=radius)
  File "C:\Users\YGS_Tu\Desktop\code\python\qt0223\..\qt0223\pic_code\Code\code_process\imgRun.py", line 33, in process_log
    img = cv.cvtColor(cv.imread(path_read), cv.COLOR_RGB2GRAY)
cv2.error: OpenCV(4.7.0) D:\a\opencv-python\opencv-python\opencv\modules\imgproc\src\color.cpp:182: error: (-215:Assertion failed) !_src.empty() in function 'cv::cvtColor'


2024-02-28 16:23:19,147 - LogController.py[line:87] - ERROR: Traceback (most recent call last):
  File "C:\Users\YGS_Tu\Desktop\code\python\qt0223\..\qt0223\controller\PicController.py", line 64, in run
    judge_flag, self.gray_aver, self.nature_aver = Main.imgProcess(
  File "C:\Users\YGS_Tu\Desktop\code\python\qt0223\..\qt0223\pic_code\img_main.py", line 27, in imgProcess
    flag, gray, nature = self.Pro.process_log(path_read=read, path_write=write, combina=combina, radius=radius)
  File "C:\Users\YGS_Tu\Desktop\code\python\qt0223\..\qt0223\pic_code\Code\code_process\imgRun.py", line 33, in process_log
    img = cv.cvtColor(cv.imread(path_read), cv.COLOR_RGB2GRAY)
cv2.error: OpenCV(4.7.0) D:\a\opencv-python\opencv-python\opencv\modules\imgproc\src\color.cpp:182: error: (-215:Assertion failed) !_src.empty() in function 'cv::cvtColor'


2024-02-28 16:23:19,147 - LogController.py[line:87] - ERROR: Traceback (most recent call last):
  File "C:\Users\YGS_Tu\Desktop\code\python\qt0223\..\qt0223\controller\PicController.py", line 64, in run
    judge_flag, self.gray_aver, self.nature_aver = Main.imgProcess(
  File "C:\Users\YGS_Tu\Desktop\code\python\qt0223\..\qt0223\pic_code\img_main.py", line 27, in imgProcess
    flag, gray, nature = self.Pro.process_log(path_read=read, path_write=write, combina=combina, radius=radius)
  File "C:\Users\YGS_Tu\Desktop\code\python\qt0223\..\qt0223\pic_code\Code\code_process\imgRun.py", line 33, in process_log
    img = cv.cvtColor(cv.imread(path_read), cv.COLOR_RGB2GRAY)
cv2.error: OpenCV(4.7.0) D:\a\opencv-python\opencv-python\opencv\modules\imgproc\src\color.cpp:182: error: (-215:Assertion failed) !_src.empty() in function 'cv::cvtColor'


2024-02-28 16:28:36,781 - LogController.py[line:87] - ERROR: Traceback (most recent call last):
  File "C:\Users\YGS_Tu\Desktop\code\python\qt0223\..\qt0223\controller\PicController.py", line 69, in run
    judge_flag, self.gray_aver, self.nature_aver = Main.imgProcess(
  File "C:\Users\YGS_Tu\Desktop\code\python\qt0223\..\qt0223\pic_code\img_main.py", line 27, in imgProcess
    flag, gray, nature = self.Pro.process_log(path_read=read, path_write=write, combina=combina, radius=radius)
  File "C:\Users\YGS_Tu\Desktop\code\python\qt0223\..\qt0223\pic_code\Code\code_process\imgRun.py", line 33, in process_log
    img = cv.cvtColor(cv.imread(path_read), cv.COLOR_RGB2GRAY)
cv2.error: OpenCV(4.7.0) D:\a\opencv-python\opencv-python\opencv\modules\imgproc\src\color.cpp:182: error: (-215:Assertion failed) !_src.empty() in function 'cv::cvtColor'


2024-02-28 16:28:36,781 - LogController.py[line:87] - ERROR: Traceback (most recent call last):
  File "C:\Users\YGS_Tu\Desktop\code\python\qt0223\..\qt0223\controller\PicController.py", line 69, in run
    judge_flag, self.gray_aver, self.nature_aver = Main.imgProcess(
  File "C:\Users\YGS_Tu\Desktop\code\python\qt0223\..\qt0223\pic_code\img_main.py", line 27, in imgProcess
    flag, gray, nature = self.Pro.process_log(path_read=read, path_write=write, combina=combina, radius=radius)
  File "C:\Users\YGS_Tu\Desktop\code\python\qt0223\..\qt0223\pic_code\Code\code_process\imgRun.py", line 33, in process_log
    img = cv.cvtColor(cv.imread(path_read), cv.COLOR_RGB2GRAY)
cv2.error: OpenCV(4.7.0) D:\a\opencv-python\opencv-python\opencv\modules\imgproc\src\color.cpp:182: error: (-215:Assertion failed) !_src.empty() in function 'cv::cvtColor'


2024-02-28 16:30:28,295 - LogController.py[line:87] - ERROR: Traceback (most recent call last):
  File "C:\Users\YGS_Tu\Desktop\code\python\qt0223\..\qt0223\controller\PicController.py", line 64, in run
    judge_flag, self.gray_aver, self.nature_aver = Main.imgProcess(
  File "C:\Users\YGS_Tu\Desktop\code\python\qt0223\..\qt0223\pic_code\img_main.py", line 27, in imgProcess
    flag, gray, nature = self.Pro.process_log(path_read=read, path_write=write, combina=combina, radius=radius)
  File "C:\Users\YGS_Tu\Desktop\code\python\qt0223\..\qt0223\pic_code\Code\code_process\imgRun.py", line 33, in process_log
    img = cv.cvtColor(cv.imread(path_read), cv.COLOR_RGB2GRAY)
cv2.error: OpenCV(4.7.0) D:\a\opencv-python\opencv-python\opencv\modules\imgproc\src\color.cpp:182: error: (-215:Assertion failed) !_src.empty() in function 'cv::cvtColor'


2024-02-28 16:30:28,296 - LogController.py[line:87] - ERROR: Traceback (most recent call last):
  File "C:\Users\YGS_Tu\Desktop\code\python\qt0223\..\qt0223\controller\PicController.py", line 64, in run
    judge_flag, self.gray_aver, self.nature_aver = Main.imgProcess(
  File "C:\Users\YGS_Tu\Desktop\code\python\qt0223\..\qt0223\pic_code\img_main.py", line 27, in imgProcess
    flag, gray, nature = self.Pro.process_log(path_read=read, path_write=write, combina=combina, radius=radius)
  File "C:\Users\YGS_Tu\Desktop\code\python\qt0223\..\qt0223\pic_code\Code\code_process\imgRun.py", line 33, in process_log
    img = cv.cvtColor(cv.imread(path_read), cv.COLOR_RGB2GRAY)
cv2.error: OpenCV(4.7.0) D:\a\opencv-python\opencv-python\opencv\modules\imgproc\src\color.cpp:182: error: (-215:Assertion failed) !_src.empty() in function 'cv::cvtColor'


2024-02-28 16:32:53,660 - LogController.py[line:87] - ERROR: Traceback (most recent call last):
  File "C:\Users\YGS_Tu\Desktop\code\python\qt0223\..\qt0223\controller\PicController.py", line 64, in run
    judge_flag, self.gray_aver, self.nature_aver = Main.imgProcess(
  File "C:\Users\YGS_Tu\Desktop\code\python\qt0223\..\qt0223\pic_code\img_main.py", line 27, in imgProcess
    flag, gray, nature = self.Pro.process_log(path_read=read, path_write=write, combina=combina, radius=radius)
  File "C:\Users\YGS_Tu\Desktop\code\python\qt0223\..\qt0223\pic_code\Code\code_process\imgRun.py", line 33, in process_log
    img = cv.cvtColor(cv.imread(path_read), cv.COLOR_RGB2GRAY)
cv2.error: OpenCV(4.7.0) D:\a\opencv-python\opencv-python\opencv\modules\imgproc\src\color.cpp:182: error: (-215:Assertion failed) !_src.empty() in function 'cv::cvtColor'


2024-02-28 16:32:53,662 - LogController.py[line:87] - ERROR: Traceback (most recent call last):
  File "C:\Users\YGS_Tu\Desktop\code\python\qt0223\..\qt0223\controller\PicController.py", line 64, in run
    judge_flag, self.gray_aver, self.nature_aver = Main.imgProcess(
  File "C:\Users\YGS_Tu\Desktop\code\python\qt0223\..\qt0223\pic_code\img_main.py", line 27, in imgProcess
    flag, gray, nature = self.Pro.process_log(path_read=read, path_write=write, combina=combina, radius=radius)
  File "C:\Users\YGS_Tu\Desktop\code\python\qt0223\..\qt0223\pic_code\Code\code_process\imgRun.py", line 33, in process_log
    img = cv.cvtColor(cv.imread(path_read), cv.COLOR_RGB2GRAY)
cv2.error: OpenCV(4.7.0) D:\a\opencv-python\opencv-python\opencv\modules\imgproc\src\color.cpp:182: error: (-215:Assertion failed) !_src.empty() in function 'cv::cvtColor'


2024-02-28 16:34:42,961 - LogController.py[line:87] - ERROR: Traceback (most recent call last):
  File "C:\Users\YGS_Tu\Desktop\code\python\qt0223\..\qt0223\controller\PicController.py", line 64, in run
    judge_flag, self.gray_aver, self.nature_aver = Main.imgProcess(
  File "C:\Users\YGS_Tu\Desktop\code\python\qt0223\..\qt0223\pic_code\img_main.py", line 27, in imgProcess
    flag, gray, nature = self.Pro.process_log(path_read=read, path_write=write, combina=combina, radius=radius)
  File "C:\Users\YGS_Tu\Desktop\code\python\qt0223\..\qt0223\pic_code\Code\code_process\imgRun.py", line 33, in process_log
    img = cv.cvtColor(cv.imread(path_read), cv.COLOR_RGB2GRAY)
cv2.error: OpenCV(4.7.0) D:\a\opencv-python\opencv-python\opencv\modules\imgproc\src\color.cpp:182: error: (-215:Assertion failed) !_src.empty() in function 'cv::cvtColor'


2024-02-28 16:34:42,961 - LogController.py[line:87] - ERROR: Traceback (most recent call last):
  File "C:\Users\YGS_Tu\Desktop\code\python\qt0223\..\qt0223\controller\PicController.py", line 64, in run
    judge_flag, self.gray_aver, self.nature_aver = Main.imgProcess(
  File "C:\Users\YGS_Tu\Desktop\code\python\qt0223\..\qt0223\pic_code\img_main.py", line 27, in imgProcess
    flag, gray, nature = self.Pro.process_log(path_read=read, path_write=write, combina=combina, radius=radius)
  File "C:\Users\YGS_Tu\Desktop\code\python\qt0223\..\qt0223\pic_code\Code\code_process\imgRun.py", line 33, in process_log
    img = cv.cvtColor(cv.imread(path_read), cv.COLOR_RGB2GRAY)
cv2.error: OpenCV(4.7.0) D:\a\opencv-python\opencv-python\opencv\modules\imgproc\src\color.cpp:182: error: (-215:Assertion failed) !_src.empty() in function 'cv::cvtColor'


2024-02-28 16:36:49,069 - LogController.py[line:87] - ERROR: Traceback (most recent call last):
  File "C:\Users\YGS_Tu\Desktop\code\python\qt0223\controller\PicController.py", line 64, in run
    judge_flag, self.gray_aver, self.nature_aver = Main.imgProcess(
  File "C:\Users\YGS_Tu\Desktop\code\python\qt0223\pic_code\img_main.py", line 27, in imgProcess
    flag, gray, nature = self.Pro.process_log(path_read=read, path_write=write, combina=combina, radius=radius)
  File "C:\Users\YGS_Tu\Desktop\code\python\qt0223\pic_code\Code\code_process\imgRun.py", line 33, in process_log
    img = cv.cvtColor(cv.imread(path_read), cv.COLOR_RGB2GRAY)
cv2.error: OpenCV(4.9.0) D:\a\opencv-python\opencv-python\opencv\modules\imgproc\src\color.cpp:196: error: (-215:Assertion failed) !_src.empty() in function 'cv::cvtColor'


2024-02-28 16:36:49,069 - LogController.py[line:87] - ERROR: Traceback (most recent call last):
  File "C:\Users\YGS_Tu\Desktop\code\python\qt0223\controller\PicController.py", line 64, in run
    judge_flag, self.gray_aver, self.nature_aver = Main.imgProcess(
  File "C:\Users\YGS_Tu\Desktop\code\python\qt0223\pic_code\img_main.py", line 27, in imgProcess
    flag, gray, nature = self.Pro.process_log(path_read=read, path_write=write, combina=combina, radius=radius)
  File "C:\Users\YGS_Tu\Desktop\code\python\qt0223\pic_code\Code\code_process\imgRun.py", line 33, in process_log
    img = cv.cvtColor(cv.imread(path_read), cv.COLOR_RGB2GRAY)
cv2.error: OpenCV(4.9.0) D:\a\opencv-python\opencv-python\opencv\modules\imgproc\src\color.cpp:196: error: (-215:Assertion failed) !_src.empty() in function 'cv::cvtColor'


2024-02-28 16:39:44,822 - LogController.py[line:87] - ERROR: Traceback (most recent call last):
  File "C:\Users\YGS_Tu\Desktop\code\python\qt0223\controller\PicController.py", line 70, in run
    judge_flag, self.gray_aver, self.nature_aver = Main.imgProcess(
  File "C:\Users\YGS_Tu\Desktop\code\python\qt0223\pic_code\img_main.py", line 27, in imgProcess
    flag, gray, nature = self.Pro.process_log(path_read=read, path_write=write, combina=combina, radius=radius)
  File "C:\Users\YGS_Tu\Desktop\code\python\qt0223\pic_code\Code\code_process\imgRun.py", line 33, in process_log
    img = cv.cvtColor(cv.imread(path_read), cv.COLOR_RGB2GRAY)
cv2.error: OpenCV(4.9.0) D:\a\opencv-python\opencv-python\opencv\modules\imgproc\src\color.cpp:196: error: (-215:Assertion failed) !_src.empty() in function 'cv::cvtColor'


2024-02-28 16:39:44,822 - LogController.py[line:87] - ERROR: Traceback (most recent call last):
  File "C:\Users\YGS_Tu\Desktop\code\python\qt0223\controller\PicController.py", line 70, in run
    judge_flag, self.gray_aver, self.nature_aver = Main.imgProcess(
  File "C:\Users\YGS_Tu\Desktop\code\python\qt0223\pic_code\img_main.py", line 27, in imgProcess
    flag, gray, nature = self.Pro.process_log(path_read=read, path_write=write, combina=combina, radius=radius)
  File "C:\Users\YGS_Tu\Desktop\code\python\qt0223\pic_code\Code\code_process\imgRun.py", line 33, in process_log
    img = cv.cvtColor(cv.imread(path_read), cv.COLOR_RGB2GRAY)
cv2.error: OpenCV(4.9.0) D:\a\opencv-python\opencv-python\opencv\modules\imgproc\src\color.cpp:196: error: (-215:Assertion failed) !_src.empty() in function 'cv::cvtColor'


2024-02-28 16:40:31,375 - LogController.py[line:87] - ERROR: Traceback (most recent call last):
  File "C:\Users\YGS_Tu\Desktop\code\python\qt0223\view\TestPage.py", line 386, in takePicture
    flag_bool = cv.imwrite(save_path, img_origin)
cv2.error: OpenCV(4.9.0) D:\a\opencv-python\opencv-python\opencv\modules\imgcodecs\src\loadsave.cpp:786: error: (-215:Assertion failed) !_img.empty() in function 'cv::imwrite'


2024-02-28 16:40:31,375 - LogController.py[line:87] - ERROR: Traceback (most recent call last):
  File "C:\Users\YGS_Tu\Desktop\code\python\qt0223\view\TestPage.py", line 386, in takePicture
    flag_bool = cv.imwrite(save_path, img_origin)
cv2.error: OpenCV(4.9.0) D:\a\opencv-python\opencv-python\opencv\modules\imgcodecs\src\loadsave.cpp:786: error: (-215:Assertion failed) !_img.empty() in function 'cv::imwrite'


2024-02-28 16:41:08,279 - LogController.py[line:87] - ERROR: Traceback (most recent call last):
  File "C:\Users\YGS_Tu\Desktop\code\python\qt0223\view\LoadPage.py", line 164, in blinkIcon
    def blinkIcon(self) -> None:
KeyboardInterrupt

2024-02-28 16:41:08,279 - LogController.py[line:87] - ERROR: Traceback (most recent call last):
  File "C:\Users\YGS_Tu\Desktop\code\python\qt0223\view\LoadPage.py", line 164, in blinkIcon
    def blinkIcon(self) -> None:
KeyboardInterrupt

2024-02-28 17:16:11,374 - LogController.py[line:87] - ERROR: Traceback (most recent call last):
  File "C:\Users\YGS_Tu\Desktop\code\python\qt0223\view\TestPage.py", line 398, in takePicture
    flag_bool = cv.imwrite(save_path, img_show_origin)
cv2.error: OpenCV(4.9.0) D:\a\opencv-python\opencv-python\opencv\modules\imgcodecs\src\loadsave.cpp:786: error: (-215:Assertion failed) !_img.empty() in function 'cv::imwrite'


2024-02-28 17:16:11,374 - LogController.py[line:87] - ERROR: Traceback (most recent call last):
  File "C:\Users\YGS_Tu\Desktop\code\python\qt0223\view\TestPage.py", line 398, in takePicture
    flag_bool = cv.imwrite(save_path, img_show_origin)
cv2.error: OpenCV(4.9.0) D:\a\opencv-python\opencv-python\opencv\modules\imgcodecs\src\loadsave.cpp:786: error: (-215:Assertion failed) !_img.empty() in function 'cv::imwrite'


2024-02-28 17:25:22,122 - LogController.py[line:87] - ERROR: Traceback (most recent call last):
  File "C:\Users\YGS_Tu\Desktop\code\python\qt0223\view\LoginPage.py", line 180, in on_loginBtn_clicked
    print("send msg")
OSError: [Errno 22] Invalid argument

2024-02-28 17:25:22,123 - LogController.py[line:87] - ERROR: Traceback (most recent call last):
  File "C:\Users\YGS_Tu\Desktop\code\python\qt0223\view\LoginPage.py", line 180, in on_loginBtn_clicked
    print("send msg")
OSError: [Errno 22] Invalid argument

2024-02-28 17:25:29,781 - LogController.py[line:87] - ERROR: Traceback (most recent call last):
  File "C:\Users\YGS_Tu\Desktop\code\python\qt0223\view\LoginPage.py", line 180, in on_loginBtn_clicked
    print("send msg")
OSError: [Errno 22] Invalid argument

2024-02-28 17:25:29,781 - LogController.py[line:87] - ERROR: Traceback (most recent call last):
  File "C:\Users\YGS_Tu\Desktop\code\python\qt0223\view\LoginPage.py", line 180, in on_loginBtn_clicked
    print("send msg")
OSError: [Errno 22] Invalid argument

2024-02-28 17:25:32,618 - LogController.py[line:87] - ERROR: Traceback (most recent call last):
  File "C:\Users\YGS_Tu\Desktop\code\python\qt0223\view\LoginPage.py", line 180, in on_loginBtn_clicked
    print("send msg")
OSError: [Errno 22] Invalid argument

2024-02-28 17:25:32,618 - LogController.py[line:87] - ERROR: Traceback (most recent call last):
  File "C:\Users\YGS_Tu\Desktop\code\python\qt0223\view\LoginPage.py", line 180, in on_loginBtn_clicked
    print("send msg")
OSError: [Errno 22] Invalid argument

