2024-03-04 14:13:22,570 - LogController.py[line:87] - ERROR: Traceback (most recent call last):
  File "C:\Users\YGS_Tu\Desktop\code\python\qt0223\controller\UpdateController.py", line 43, in run
    with zipfile.ZipFile(MY_ZIP, 'r') as zip_ref:
  File "C:\Program Files\Python39\lib\zipfile.py", line 1239, in __init__
    self.fp = io.open(file, filemode)
FileNotFoundError: [Errno 2] No such file or directory: 'C:\\Users\\YGS_Tu\\Desktop\\code\\python\\qt0223/update.zip'

2024-03-04 14:13:29,767 - LogController.py[line:87] - ERROR: Traceback (most recent call last):
  File "C:\Users\YGS_Tu\Desktop\code\python\qt0223\controller\UpdateController.py", line 43, in run
    with zipfile.ZipFile(MY_ZIP, 'r') as zip_ref:
  File "C:\Program Files\Python39\lib\zipfile.py", line 1239, in __init__
    self.fp = io.open(file, filemode)
FileNotFoundError: [Errno 2] No such file or directory: 'C:\\Users\\YGS_Tu\\Desktop\\code\\python\\qt0223/update.zip'

